Workbook

Sheet Summary
A5: Yaş Kateqoriyaları
A6: 0=<20
A7: 20=<30
A8: 30=<40
A9: 40=<60
A10: 60=<…
A14: Seher/Yas kateqoriya | B14: 0=<20 | C14: 20=<30 | D14: 30=<40 | E14: 40=<60 | F14: 60=< | G14: Toplam
A15: Quba | B15: =COUNTIFS(Raw!$G:$G,Summary!$A15,Raw!$F:$F,Summary!B$14) -> 0 | C15: =COUNTIFS(Raw!$G:$G,Summary!$A15,Raw!$F:$F,Summary!C$14) -> 12 | D15: =COUNTIFS(Raw!$G:$G,Summary!$A15,Raw!$F:$F,Summary!D$14) -> 14 | E15: =COUNTIFS(Raw!$G:$G,Summary!$A15,Raw!$F:$F,Summary!E$14) -> 26 | F15: =COUNTIFS(Raw!$G:$G,Summary!$A15,Raw!$F:$F,Summary!F$14) -> 14 | G15: =SUM(B15:F15) -> 66
A16: Xaçmaz | B16: =COUNTIFS(Raw!$G:$G,Summary!$A16,Raw!$F:$F,Summary!B$14) -> 0 | C16: =COUNTIFS(Raw!$G:$G,Summary!$A16,Raw!$F:$F,Summary!C$14) -> 13 | D16: =COUNTIFS(Raw!$G:$G,Summary!$A16,Raw!$F:$F,Summary!D$14) -> 19 | E16: =COUNTIFS(Raw!$G:$G,Summary!$A16,Raw!$F:$F,Summary!E$14) -> 22 | F16: =COUNTIFS(Raw!$G:$G,Summary!$A16,Raw!$F:$F,Summary!F$14) -> 7 | G16: =SUM(B16:F16) -> 61
A17: Tovuz | B17: =COUNTIFS(Raw!$G:$G,Summary!$A17,Raw!$F:$F,Summary!B$14) -> 0 | C17: =COUNTIFS(Raw!$G:$G,Summary!$A17,Raw!$F:$F,Summary!C$14) -> 13 | D17: =COUNTIFS(Raw!$G:$G,Summary!$A17,Raw!$F:$F,Summary!D$14) -> 15 | E17: =COUNTIFS(Raw!$G:$G,Summary!$A17,Raw!$F:$F,Summary!E$14) -> 37 | F17: =COUNTIFS(Raw!$G:$G,Summary!$A17,Raw!$F:$F,Summary!F$14) -> 3 | G17: =SUM(B17:F17) -> 68
A18: Qəbələ | B18: =COUNTIFS(Raw!$G:$G,Summary!$A18,Raw!$F:$F,Summary!B$14) -> 0 | C18: =COUNTIFS(Raw!$G:$G,Summary!$A18,Raw!$F:$F,Summary!C$14) -> 9 | D18: =COUNTIFS(Raw!$G:$G,Summary!$A18,Raw!$F:$F,Summary!D$14) -> 21 | E18: =COUNTIFS(Raw!$G:$G,Summary!$A18,Raw!$F:$F,Summary!E$14) -> 24 | F18: =COUNTIFS(Raw!$G:$G,Summary!$A18,Raw!$F:$F,Summary!F$14) -> 8 | G18: =SUM(B18:F18) -> 62
A19: Dəvəçi | B19: =COUNTIFS(Raw!$G:$G,Summary!$A19,Raw!$F:$F,Summary!B$14) -> 0 | C19: =COUNTIFS(Raw!$G:$G,Summary!$A19,Raw!$F:$F,Summary!C$14) -> 11 | D19: =COUNTIFS(Raw!$G:$G,Summary!$A19,Raw!$F:$F,Summary!D$14) -> 10 | E19: =COUNTIFS(Raw!$G:$G,Summary!$A19,Raw!$F:$F,Summary!E$14) -> 28 | F19: =COUNTIFS(Raw!$G:$G,Summary!$A19,Raw!$F:$F,Summary!F$14) -> 6 | G19: =SUM(B19:F19) -> 55
A20: Şərur | B20: =COUNTIFS(Raw!$G:$G,Summary!$A20,Raw!$F:$F,Summary!B$14) -> 0 | C20: =COUNTIFS(Raw!$G:$G,Summary!$A20,Raw!$F:$F,Summary!C$14) -> 9 | D20: =COUNTIFS(Raw!$G:$G,Summary!$A20,Raw!$F:$F,Summary!D$14) -> 12 | E20: =COUNTIFS(Raw!$G:$G,Summary!$A20,Raw!$F:$F,Summary!E$14) -> 27 | F20: =COUNTIFS(Raw!$G:$G,Summary!$A20,Raw!$F:$F,Summary!F$14) -> 8 | G20: =SUM(B20:F20) -> 56
A21: Şəki | B21: =COUNTIFS(Raw!$G:$G,Summary!$A21,Raw!$F:$F,Summary!B$14) -> 0 | C21: =COUNTIFS(Raw!$G:$G,Summary!$A21,Raw!$F:$F,Summary!C$14) -> 6 | D21: =COUNTIFS(Raw!$G:$G,Summary!$A21,Raw!$F:$F,Summary!D$14) -> 14 | E21: =COUNTIFS(Raw!$G:$G,Summary!$A21,Raw!$F:$F,Summary!E$14) -> 34 | F21: =COUNTIFS(Raw!$G:$G,Summary!$A21,Raw!$F:$F,Summary!F$14) -> 11 | G21: =SUM(B21:F21) -> 65
A22: Lənkəran | B22: =COUNTIFS(Raw!$G:$G,Summary!$A22,Raw!$F:$F,Summary!B$14) -> 0 | C22: =COUNTIFS(Raw!$G:$G,Summary!$A22,Raw!$F:$F,Summary!C$14) -> 15 | D22: =COUNTIFS(Raw!$G:$G,Summary!$A22,Raw!$F:$F,Summary!D$14) -> 11 | E22: =COUNTIFS(Raw!$G:$G,Summary!$A22,Raw!$F:$F,Summary!E$14) -> 25 | F22: =COUNTIFS(Raw!$G:$G,Summary!$A22,Raw!$F:$F,Summary!F$14) -> 8 | G22: =SUM(B22:F22) -> 59
A23: Gəncə | B23: =COUNTIFS(Raw!$G:$G,Summary!$A23,Raw!$F:$F,Summary!B$14) -> 0 | C23: =COUNTIFS(Raw!$G:$G,Summary!$A23,Raw!$F:$F,Summary!C$14) -> 10 | D23: =COUNTIFS(Raw!$G:$G,Summary!$A23,Raw!$F:$F,Summary!D$14) -> 22 | E23: =COUNTIFS(Raw!$G:$G,Summary!$A23,Raw!$F:$F,Summary!E$14) -> 34 | F23: =COUNTIFS(Raw!$G:$G,Summary!$A23,Raw!$F:$F,Summary!F$14) -> 6 | G23: =SUM(B23:F23) -> 72
A24: Bakı | B24: =COUNTIFS(Raw!$G:$G,Summary!$A24,Raw!$F:$F,Summary!B$14) -> 0 | C24: =COUNTIFS(Raw!$G:$G,Summary!$A24,Raw!$F:$F,Summary!C$14) -> 3 | D24: =COUNTIFS(Raw!$G:$G,Summary!$A24,Raw!$F:$F,Summary!D$14) -> 13 | E24: =COUNTIFS(Raw!$G:$G,Summary!$A24,Raw!$F:$F,Summary!E$14) -> 28 | F24: =COUNTIFS(Raw!$G:$G,Summary!$A24,Raw!$F:$F,Summary!F$14) -> 5 | G24: =SUM(B24:F24) -> 49
A25: Toplam | B25: =SUM(B15:B24) -> 0 | C25: =SUM(C15:C24) -> 101 | D25: =SUM(D15:D24) -> 151 | E25: =SUM(E15:E24) -> 285 | F25: =SUM(F15:F24) -> 76 | G25: =SUM(G15:G24) -> 613
A52: Seher/Yas kateqoriya | B52: 0=<20 | C52: 20=<30 | D52: 30=<40 | E52: 40=<60 | F52: 60=< | G52: Toplam
A53: Quba | B53: =SUMIFS(Raw!$H:$H,Raw!$G:$G,Summary!$A53,Raw!$F:$F,Summary!B$52) -> 0 | C53: =SUMIFS(Raw!$H:$H,Raw!$G:$G,Summary!$A53,Raw!$F:$F,Summary!C$52) -> 23205.08 | D53: =SUMIFS(Raw!$H:$H,Raw!$G:$G,Summary!$A53,Raw!$F:$F,Summary!D$52) -> 39906.59 | E53: =SUMIFS(Raw!$H:$H,Raw!$G:$G,Summary!$A53,Raw!$F:$F,Summary!E$52) -> 71090.85 | F53: =SUMIFS(Raw!$H:$H,Raw!$G:$G,Summary!$A53,Raw!$F:$F,Summary!F$52) -> 36989.32 | G53: =SUM(B53:F53) -> 171191.84
A54: Xaçmaz | B54: =SUMIFS(Raw!$H:$H,Raw!$G:$G,Summary!$A54,Raw!$F:$F,Summary!B$52) -> 0 | C54: =SUMIFS(Raw!$H:$H,Raw!$G:$G,Summary!$A54,Raw!$F:$F,Summary!C$52) -> 37873.43 | D54: =SUMIFS(Raw!$H:$H,Raw!$G:$G,Summary!$A54,Raw!$F:$F,Summary!D$52) -> 43316.77 | E54: =SUMIFS(Raw!$H:$H,Raw!$G:$G,Summary!$A54,Raw!$F:$F,Summary!E$52) -> 59310.03 | F54: =SUMIFS(Raw!$H:$H,Raw!$G:$G,Summary!$A54,Raw!$F:$F,Summary!F$52) -> 9948.9 | G54: =SUM(B54:F54) -> 150449.13
A55: Tovuz | B55: =SUMIFS(Raw!$H:$H,Raw!$G:$G,Summary!$A55,Raw!$F:$F,Summary!B$52) -> 0 | C55: =SUMIFS(Raw!$H:$H,Raw!$G:$G,Summary!$A55,Raw!$F:$F,Summary!C$52) -> 37934.85 | D55: =SUMIFS(Raw!$H:$H,Raw!$G:$G,Summary!$A55,Raw!$F:$F,Summary!D$52) -> 42266.25 | E55: =SUMIFS(Raw!$H:$H,Raw!$G:$G,Summary!$A55,Raw!$F:$F,Summary!E$52) -> 82905.03 | F55: =SUMIFS(Raw!$H:$H,Raw!$G:$G,Summary!$A55,Raw!$F:$F,Summary!F$52) -> 8117.85 | G55: =SUM(B55:F55) -> 171223.98
A56: Qəbələ | B56: =SUMIFS(Raw!$H:$H,Raw!$G:$G,Summary!$A56,Raw!$F:$F,Summary!B$52) -> 0 | C56: =SUMIFS(Raw!$H:$H,Raw!$G:$G,Summary!$A56,Raw!$F:$F,Summary!C$52) -> 21578.22 | D56: =SUMIFS(Raw!$H:$H,Raw!$G:$G,Summary!$A56,Raw!$F:$F,Summary!D$52) -> 65590.5 | E56: =SUMIFS(Raw!$H:$H,Raw!$G:$G,Summary!$A56,Raw!$F:$F,Summary!E$52) -> 69887.84 | F56: =SUMIFS(Raw!$H:$H,Raw!$G:$G,Summary!$A56,Raw!$F:$F,Summary!F$52) -> 22048.15 | G56: =SUM(B56:F56) -> 179104.71
A57: Dəvəçi | B57: =SUMIFS(Raw!$H:$H,Raw!$G:$G,Summary!$A57,Raw!$F:$F,Summary!B$52) -> 0 | C57: =SUMIFS(Raw!$H:$H,Raw!$G:$G,Summary!$A57,Raw!$F:$F,Summary!C$52) -> 27546.66 | D57: =SUMIFS(Raw!$H:$H,Raw!$G:$G,Summary!$A57,Raw!$F:$F,Summary!D$52) -> 22033.23 | E57: =SUMIFS(Raw!$H:$H,Raw!$G:$G,Summary!$A57,Raw!$F:$F,Summary!E$52) -> 70891.28 | F57: =SUMIFS(Raw!$H:$H,Raw!$G:$G,Summary!$A57,Raw!$F:$F,Summary!F$52) -> 14441.54 | G57: =SUM(B57:F57) -> 134912.71
A58: Şərur | B58: =SUMIFS(Raw!$H:$H,Raw!$G:$G,Summary!$A58,Raw!$F:$F,Summary!B$52) -> 0 | C58: =SUMIFS(Raw!$H:$H,Raw!$G:$G,Summary!$A58,Raw!$F:$F,Summary!C$52) -> 23558.88 | D58: =SUMIFS(Raw!$H:$H,Raw!$G:$G,Summary!$A58,Raw!$F:$F,Summary!D$52) -> 30986.94 | E58: =SUMIFS(Raw!$H:$H,Raw!$G:$G,Summary!$A58,Raw!$F:$F,Summary!E$52) -> 64935.04 | F58: =SUMIFS(Raw!$H:$H,Raw!$G:$G,Summary!$A58,Raw!$F:$F,Summary!F$52) -> 22246.76 | G58: =SUM(B58:F58) -> 141727.62
A59: Şəki | B59: =SUMIFS(Raw!$H:$H,Raw!$G:$G,Summary!$A59,Raw!$F:$F,Summary!B$52) -> 0 | C59: =SUMIFS(Raw!$H:$H,Raw!$G:$G,Summary!$A59,Raw!$F:$F,Summary!C$52) -> 20833.09 | D59: =SUMIFS(Raw!$H:$H,Raw!$G:$G,Summary!$A59,Raw!$F:$F,Summary!D$52) -> 36657.91 | E59: =SUMIFS(Raw!$H:$H,Raw!$G:$G,Summary!$A59,Raw!$F:$F,Summary!E$52) -> 84683.05 | F59: =SUMIFS(Raw!$H:$H,Raw!$G:$G,Summary!$A59,Raw!$F:$F,Summary!F$52) -> 35319.74 | G59: =SUM(B59:F59) -> 177493.79
A60: Lənkəran | B60: =SUMIFS(Raw!$H:$H,Raw!$G:$G,Summary!$A60,Raw!$F:$F,Summary!B$52) -> 0 | C60: =SUMIFS(Raw!$H:$H,Raw!$G:$G,Summary!$A60,Raw!$F:$F,Summary!C$52) -> 40577.8 | D60: =SUMIFS(Raw!$H:$H,Raw!$G:$G,Summary!$A60,Raw!$F:$F,Summary!D$52) -> 21824.71 | E60: =SUMIFS(Raw!$H:$H,Raw!$G:$G,Summary!$A60,Raw!$F:$F,Summary!E$52) -> 72864.96 | F60: =SUMIFS(Raw!$H:$H,Raw!$G:$G,Summary!$A60,Raw!$F:$F,Summary!F$52) -> 17620.33 | G60: =SUM(B60:F60) -> 152887.8
A61: Gəncə | B61: =SUMIFS(Raw!$H:$H,Raw!$G:$G,Summary!$A61,Raw!$F:$F,Summary!B$52) -> 0 | C61: =SUMIFS(Raw!$H:$H,Raw!$G:$G,Summary!$A61,Raw!$F:$F,Summary!C$52) -> 27593.08 | D61: =SUMIFS(Raw!$H:$H,Raw!$G:$G,Summary!$A61,Raw!$F:$F,Summary!D$52) -> 59001.74 | E61: =SUMIFS(Raw!$H:$H,Raw!$G:$G,Summary!$A61,Raw!$F:$F,Summary!E$52) -> 85331.91 | F61: =SUMIFS(Raw!$H:$H,Raw!$G:$G,Summary!$A61,Raw!$F:$F,Summary!F$52) -> 15752.61 | G61: =SUM(B61:F61) -> 187679.34
A62: Bakı | B62: =SUMIFS(Raw!$H:$H,Raw!$G:$G,Summary!$A62,Raw!$F:$F,Summary!B$52) -> 0 | C62: =SUMIFS(Raw!$H:$H,Raw!$G:$G,Summary!$A62,Raw!$F:$F,Summary!C$52) -> 6867.68 | D62: =SUMIFS(Raw!$H:$H,Raw!$G:$G,Summary!$A62,Raw!$F:$F,Summary!D$52) -> 38613.9 | E62: =SUMIFS(Raw!$H:$H,Raw!$G:$G,Summary!$A62,Raw!$F:$F,Summary!E$52) -> 69180.07 | F62: =SUMIFS(Raw!$H:$H,Raw!$G:$G,Summary!$A62,Raw!$F:$F,Summary!F$52) -> 12196.43 | G62: =SUM(B62:F62) -> 126858.08
A63: Toplam | B63: =SUM(B53:B62) -> 0 | C63: =SUM(C53:C62) -> 267568.77 | D63: =SUM(D53:D62) -> 400198.54 | E63: =SUM(E53:E62) -> 731080.06 | F63: =SUM(F53:F62) -> 194681.63 | G63: =SUM(G53:G62) -> 1593529
A92: Gəlir/Xərc Kateqoriyaları
A93: …<1000 AZN
A94: 1000=<2000 AZN
A95: 2000=<3000 AZN
A96: 3000=<4000 AZN
A97: 4000=<5000 AZN
A98: 5000=<… AZN
A104: Seher/Gelir kateqoriya | B104: <1000 AZN | C104: 1000=<2000 AZN | D104: 2000=<3000 AZN | E104: 3000=<4000 AZN | F104: 4000=<5000 AZN | G104: 5000=< AZN | H104: Toplam
A105: Quba | B105: =SUMIFS(Raw!$H:$H,Raw!$G:$G,Summary!$A105,Raw!$I:$I,Summary!B$104) -> 6493.26 | C105: =SUMIFS(Raw!$H:$H,Raw!$G:$G,Summary!$A105,Raw!$I:$I,Summary!C$104) -> 18864.89 | D105: =SUMIFS(Raw!$H:$H,Raw!$G:$G,Summary!$A105,Raw!$I:$I,Summary!D$104) -> 46353.18 | E105: =SUMIFS(Raw!$H:$H,Raw!$G:$G,Summary!$A105,Raw!$I:$I,Summary!E$104) -> 54958.54 | F105: =SUMIFS(Raw!$H:$H,Raw!$G:$G,Summary!$A105,Raw!$I:$I,Summary!F$104) -> 44521.97 | G105: =SUMIFS(Raw!$H:$H,Raw!$G:$G,Summary!$A105,Raw!$I:$I,Summary!G$104) -> 0 | H105: =SUM(B105:G105) -> 171191.84
A106: Xaçmaz | B106: =SUMIFS(Raw!$H:$H,Raw!$G:$G,Summary!$A106,Raw!$I:$I,Summary!B$104) -> 7254.96 | C106: =SUMIFS(Raw!$H:$H,Raw!$G:$G,Summary!$A106,Raw!$I:$I,Summary!C$104) -> 21381.71 | D106: =SUMIFS(Raw!$H:$H,Raw!$G:$G,Summary!$A106,Raw!$I:$I,Summary!D$104) -> 38399.33 | E106: =SUMIFS(Raw!$H:$H,Raw!$G:$G,Summary!$A106,Raw!$I:$I,Summary!E$104) -> 24692.15 | F106: =SUMIFS(Raw!$H:$H,Raw!$G:$G,Summary!$A106,Raw!$I:$I,Summary!F$104) -> 58720.98 | G106: =SUMIFS(Raw!$H:$H,Raw!$G:$G,Summary!$A106,Raw!$I:$I,Summary!G$104) -> 0 | H106: =SUM(B106:G106) -> 150449.13
...

Sheet Raw
A1: Ad | B1: Soyad | C1: Doğum Tarixi | D1: dogum_tarixi_il | E1: Yaş | F1: Yaş_Kateqoriyası | G1: Şəhər | H1: Aylıq_Gəlir | I1: Gəlir Kateqoriyası | J1: Aylıq_Xərclər | K1: Xərc_Kateqoriyası | L1: Balans | M1: Balans_Növü | N1: birlesdirme
A2: Lütfiyyə | B2: Düzgün | C2: 28338 | D2: =YEAR(C2) -> 1977 | E2: =2025-D2 -> 48 | F2: =IF(AND(E2>=0,E2<20),"0=<20",IF(AND(E2>=20,E2<30),"20=<30",IF(AND(E2>=30,E2<40),"30=<40",IF(AND(E2>=40,E2<60),"40=<60",IF(AND(E2>=60),"60=<"))))) -> 40=<60 | G2: Quba | H2: 2338.12 | I2: =IF(AND(H2<1000),"<1000 AZN",IF(AND(H2>=1000,H2<2000),"1000=<2000 AZN",IF(AND(H2>=2000,H2<3000),"2000=<3000 AZN",IF(AND(H2>=3000,H2<4000),"3000=<4000 AZN",IF(AND(H2>=4000,H2<5000),"4000=<5000 AZN",IF(AND(H2>=5000,),"5000=< AZN")))))) -> 2000=<3000 AZN | J2: 3294.6 | K2: =IF(AND(J2<1000),"<1000 AZN",IF(AND(J2>=1000,J2<2000),"1000=<2000 AZN",IF(AND(J2>=2000,J2<3000),"2000=<3000 AZN",IF(AND(J2>=3000,J2<4000),"3000=<4000 AZN",IF(AND(J2>=4000,J2<5000),"4000=<5000 AZN",IF(AND(J2>=5000,),"5000=< AZN")))))) -> 3000=<4000 AZN | L2: =H2-J2 -> -956.48 | M2: =IF(L2<0,"menfi","musbet") -> menfi | N2: =_xlfn.CONCAT(A2," ",B2," ",C2) -> Lütfiyyə Düzgün 28338
A3: Ofeliya | B3: Həsənli | C3: 23447 | D3: =YEAR(C3) -> 1964 | E3: =2025-D3 -> 61 | F3: =IF(AND(E3>=0,E3<20),"0=<20",IF(AND(E3>=20,E3<30),"20=<30",IF(AND(E3>=30,E3<40),"30=<40",IF(AND(E3>=40,E3<60),"40=<60",IF(AND(E3>=60),"60=<"))))) -> 60=< | G3: Xaçmaz | H3: 811.79 | I3: =IF(AND(H3<1000),"<1000 AZN",IF(AND(H3>=1000,H3<2000),"1000=<2000 AZN",IF(AND(H3>=2000,H3<3000),"2000=<3000 AZN",IF(AND(H3>=3000,H3<4000),"3000=<4000 AZN",IF(AND(H3>=4000,H3<5000),"4000=<5000 AZN",IF(AND(H3>=5000,),"5000=< AZN")))))) -> <1000 AZN | J3: 3300.72 | K3: =IF(AND(J3<1000),"<1000 AZN",IF(AND(J3>=1000,J3<2000),"1000=<2000 AZN",IF(AND(J3>=2000,J3<3000),"2000=<3000 AZN",IF(AND(J3>=3000,J3<4000),"3000=<4000 AZN",IF(AND(J3>=4000,J3<5000),"4000=<5000 AZN",IF(AND(J3>=5000,),"5000=< AZN")))))) -> 3000=<4000 AZN | L3: =H3-J3 -> -2488.93 | M3: =IF(L3<0,"menfi","musbet") -> menfi | N3: =_xlfn.CONCAT(A3," ",B3," ",C3) -> Ofeliya Həsənli 23447
A4: Qənirə | B4: Təhmin | C4: 24827 | D4: =YEAR(C4) -> 1967 | E4: =2025-D4 -> 58 | F4: =IF(AND(E4>=0,E4<20),"0=<20",IF(AND(E4>=20,E4<30),"20=<30",IF(AND(E4>=30,E4<40),"30=<40",IF(AND(E4>=40,E4<60),"40=<60",IF(AND(E4>=60),"60=<"))))) -> 40=<60 | G4: Tovuz | H4: 432.17 | I4: =IF(AND(H4<1000),"<1000 AZN",IF(AND(H4>=1000,H4<2000),"1000=<2000 AZN",IF(AND(H4>=2000,H4<3000),"2000=<3000 AZN",IF(AND(H4>=3000,H4<4000),"3000=<4000 AZN",IF(AND(H4>=4000,H4<5000),"4000=<5000 AZN",IF(AND(H4>=5000,),"5000=< AZN")))))) -> <1000 AZN | J4: 3630.23 | K4: =IF(AND(J4<1000),"<1000 AZN",IF(AND(J4>=1000,J4<2000),"1000=<2000 AZN",IF(AND(J4>=2000,J4<3000),"2000=<3000 AZN",IF(AND(J4>=3000,J4<4000),"3000=<4000 AZN",IF(AND(J4>=4000,J4<5000),"4000=<5000 AZN",IF(AND(J4>=5000,),"5000=< AZN")))))) -> 3000=<4000 AZN | L4: =H4-J4 -> -3198.06 | M4: =IF(L4<0,"menfi","musbet") -> menfi | N4: =_xlfn.CONCAT(A4," ",B4," ",C4) -> Qənirə Təhmin 24827
A5: Şükür | B5: Düzgün | C5: 22552 | D5: =YEAR(C5) -> 1961 | E5: =2025-D5 -> 64 | F5: =IF(AND(E5>=0,E5<20),"0=<20",IF(AND(E5>=20,E5<30),"20=<30",IF(AND(E5>=30,E5<40),"30=<40",IF(AND(E5>=40,E5<60),"40=<60",IF(AND(E5>=60),"60=<"))))) -> 60=< | G5: Quba | H5: 2702.23 | I5: =IF(AND(H5<1000),"<1000 AZN",IF(AND(H5>=1000,H5<2000),"1000=<2000 AZN",IF(AND(H5>=2000,H5<3000),"2000=<3000 AZN",IF(AND(H5>=3000,H5<4000),"3000=<4000 AZN",IF(AND(H5>=4000,H5<5000),"4000=<5000 AZN",IF(AND(H5>=5000,),"5000=< AZN")))))) -> 2000=<3000 AZN | J5: 2129.49 | K5: =IF(AND(J5<1000),"<1000 AZN",IF(AND(J5>=1000,J5<2000),"1000=<2000 AZN",IF(AND(J5>=2000,J5<3000),"2000=<3000 AZN",IF(AND(J5>=3000,J5<4000),"3000=<4000 AZN",IF(AND(J5>=4000,J5<5000),"4000=<5000 AZN",IF(AND(J5>=5000,),"5000=< AZN")))))) -> 2000=<3000 AZN | L5: =H5-J5 -> 572.74 | M5: =IF(L5<0,"menfi","musbet") -> musbet | N5: =_xlfn.CONCAT(A5," ",B5," ",C5) -> Şükür Düzgün 22552
A6: Aytən | B6: Abbasbəyli | C6: 26548 | D6: =YEAR(C6) -> 1972 | E6: =2025-D6 -> 53 | F6: =IF(AND(E6>=0,E6<20),"0=<20",IF(AND(E6>=20,E6<30),"20=<30",IF(AND(E6>=30,E6<40),"30=<40",IF(AND(E6>=40,E6<60),"40=<60",IF(AND(E6>=60),"60=<"))))) -> 40=<60 | G6: Qəbələ | H6: 903.51 | I6: =IF(AND(H6<1000),"<1000 AZN",IF(AND(H6>=1000,H6<2000),"1000=<2000 AZN",IF(AND(H6>=2000,H6<3000),"2000=<3000 AZN",IF(AND(H6>=3000,H6<4000),"3000=<4000 AZN",IF(AND(H6>=4000,H6<5000),"4000=<5000 AZN",IF(AND(H6>=5000,),"5000=< AZN")))))) -> <1000 AZN | J6: 437.48 | K6: =IF(AND(J6<1000),"<1000 AZN",IF(AND(J6>=1000,J6<2000),"1000=<2000 AZN",IF(AND(J6>=2000,J6<3000),"2000=<3000 AZN",IF(AND(J6>=3000,J6<4000),"3000=<4000 AZN",IF(AND(J6>=4000,J6<5000),"4000=<5000 AZN",IF(AND(J6>=5000,),"5000=< AZN")))))) -> <1000 AZN | L6: =H6-J6 -> 466.03 | M6: =IF(L6<0,"menfi","musbet") -> musbet | N6: =_xlfn.CONCAT(A6," ",B6," ",C6) -> Aytən Abbasbəyli 26548
A7: Mənsurə | B7: Həsənli | C7: 22234 | D7: =YEAR(C7) -> 1960 | E7: =2025-D7 -> 65 | F7: =IF(AND(E7>=0,E7<20),"0=<20",IF(AND(E7>=20,E7<30),"20=<30",IF(AND(E7>=30,E7<40),"30=<40",IF(AND(E7>=40,E7<60),"40=<60",IF(AND(E7>=60),"60=<"))))) -> 60=< | G7: Dəvəçi | H7: 1169.29 | I7: =IF(AND(H7<1000),"<1000 AZN",IF(AND(H7>=1000,H7<2000),"1000=<2000 AZN",IF(AND(H7>=2000,H7<3000),"2000=<3000 AZN",IF(AND(H7>=3000,H7<4000),"3000=<4000 AZN",IF(AND(H7>=4000,H7<5000),"4000=<5000 AZN",IF(AND(H7>=5000,),"5000=< AZN")))))) -> 1000=<2000 AZN | J7: 1085.57 | K7: =IF(AND(J7<1000),"<1000 AZN",IF(AND(J7>=1000,J7<2000),"1000=<2000 AZN",IF(AND(J7>=2000,J7<3000),"2000=<3000 AZN",IF(AND(J7>=3000,J7<4000),"3000=<4000 AZN",IF(AND(J7>=4000,J7<5000),"4000=<5000 AZN",IF(AND(J7>=5000,),"5000=< AZN")))))) -> 1000=<2000 AZN | L7: =H7-J7 -> 83.72 | M7: =IF(L7<0,"menfi","musbet") -> musbet | N7: =_xlfn.CONCAT(A7," ",B7," ",C7) -> Mənsurə Həsənli 22234
A8: Ruhiyyə | B8: Vurğun | C8: 25010 | D8: =YEAR(C8) -> 1968 | E8: =2025-D8 -> 57 | F8: =IF(AND(E8>=0,E8<20),"0=<20",IF(AND(E8>=20,E8<30),"20=<30",IF(AND(E8>=30,E8<40),"30=<40",IF(AND(E8>=40,E8<60),"40=<60",IF(AND(E8>=60),"60=<"))))) -> 40=<60 | G8: Şərur | H8: 4944 | I8: =IF(AND(H8<1000),"<1000 AZN",IF(AND(H8>=1000,H8<2000),"1000=<2000 AZN",IF(AND(H8>=2000,H8<3000),"2000=<3000 AZN",IF(AND(H8>=3000,H8<4000),"3000=<4000 AZN",IF(AND(H8>=4000,H8<5000),"4000=<5000 AZN",IF(AND(H8>=5000,),"5000=< AZN")))))) -> 4000=<5000 AZN | J8: 4347.45 | K8: =IF(AND(J8<1000),"<1000 AZN",IF(AND(J8>=1000,J8<2000),"1000=<2000 AZN",IF(AND(J8>=2000,J8<3000),"2000=<3000 AZN",IF(AND(J8>=3000,J8<4000),"3000=<4000 AZN",IF(AND(J8>=4000,J8<5000),"4000=<5000 AZN",IF(AND(J8>=5000,),"5000=< AZN")))))) -> 4000=<5000 AZN | L8: =H8-J8 -> 596.55 | M8: =IF(L8<0,"menfi","musbet") -> musbet | N8: =_xlfn.CONCAT(A8," ",B8," ",C8) -> Ruhiyyə Vurğun 25010
A9: Elariz | B9: Abbasbəyli | C9: 33355 | D9: =YEAR(C9) -> 1991 | E9: =2025-D9 -> 34 | F9: =IF(AND(E9>=0,E9<20),"0=<20",IF(AND(E9>=20,E9<30),"20=<30",IF(AND(E9>=30,E9<40),"30=<40",IF(AND(E9>=40,E9<60),"40=<60",IF(AND(E9>=60),"60=<"))))) -> 30=<40 | G9: Dəvəçi | H9: 434.43 | I9: =IF(AND(H9<1000),"<1000 AZN",IF(AND(H9>=1000,H9<2000),"1000=<2000 AZN",IF(AND(H9>=2000,H9<3000),"2000=<3000 AZN",IF(AND(H9>=3000,H9<4000),"3000=<4000 AZN",IF(AND(H9>=4000,H9<5000),"4000=<5000 AZN",IF(AND(H9>=5000,),"5000=< AZN")))))) -> <1000 AZN | J9: 4714.4 | K9: =IF(AND(J9<1000),"<1000 AZN",IF(AND(J9>=1000,J9<2000),"1000=<2000 AZN",IF(AND(J9>=2000,J9<3000),"2000=<3000 AZN",IF(AND(J9>=3000,J9<4000),"3000=<4000 AZN",IF(AND(J9>=4000,J9<5000),"4000=<5000 AZN",IF(AND(J9>=5000,),"5000=< AZN")))))) -> 4000=<5000 AZN | L9: =H9-J9 -> -4279.97 | M9: =IF(L9<0,"menfi","musbet") -> menfi | N9: =_xlfn.CONCAT(A9," ",B9," ",C9) -> Elariz Abbasbəyli 33355
A10: Nihal | B10: Talıbzadə | C10: 31499 | D10: =YEAR(C10) -> 1986 | E10: =2025-D10 -> 39 | F10: =IF(AND(E10>=0,E10<20),"0=<20",IF(AND(E10>=20,E10<30),"20=<30",IF(AND(E10>=30,E10<40),"30=<40",IF(AND(E10>=40,E10<60),"40=<60",IF(AND(E10>=60),"60=<"))))) -> 30=<40 | G10: Xaçmaz | H10: 1758.22 | I10: =IF(AND(H10<1000),"<1000 AZN",IF(AND(H10>=1000,H10<2000),"1000=<2000 AZN",IF(AND(H10>=2000,H10<3000),"2000=<3000 AZN",IF(AND(H10>=3000,H10<4000),"3000=<4000 AZN",IF(AND(H10>=4000,H10<5000),"4000=<5000 AZN",IF(AND(H10>=5000,),"5000=< AZN")))))) -> 1000=<2000 AZN | J10: 4094.44 | K10: =IF(AND(J10<1000),"<1000 AZN",IF(AND(J10>=1000,J10<2000),"1000=<2000 AZN",IF(AND(J10>=2000,J10<3000),"2000=<3000 AZN",IF(AND(J10>=3000,J10<4000),"3000=<4000 AZN",IF(AND(J10>=4000,J10<5000),"4000=<5000 AZN",IF(AND(J10>=5000,),"5000=< AZN")))))) -> 4000=<5000 AZN | L10: =H10-J10 -> -2336.22 | M10: =IF(L10<0,"menfi","musbet") -> menfi | N10: =_xlfn.CONCAT(A10," ",B10," ",C10) -> Nihal Talıbzadə 31499
A11: Reyhanə | B11: Abbasbəyli | C11: 36531 | D11: =YEAR(C11) -> 2000 | E11: =2025-D11 -> 25 | F11: =IF(AND(E11>=0,E11<20),"0=<20",IF(AND(E11>=20,E11<30),"20=<30",IF(AND(E11>=30,E11<40),"30=<40",IF(AND(E11>=40,E11<60),"40=<60",IF(AND(E11>=60),"60=<"))))) -> 20=<30 | G11: Şəki | H11: 2791.71 | I11: =IF(AND(H11<1000),"<1000 AZN",IF(AND(H11>=1000,H11<2000),"1000=<2000 AZN",IF(AND(H11>=2000,H11<3000),"2000=<3000 AZN",IF(AND(H11>=3000,H11<4000),"3000=<4000 AZN",IF(AND(H11>=4000,H11<5000),"4000=<5000 AZN",IF(AND(H11>=5000,),"5000=< AZN")))))) -> 2000=<3000 AZN | J11: 2785.4 | K11: =IF(AND(J11<1000),"<1000 AZN",IF(AND(J11>=1000,J11<2000),"1000=<2000 AZN",IF(AND(J11>=2000,J11<3000),"2000=<3000 AZN",IF(AND(J11>=3000,J11<4000),"3000=<4000 AZN",IF(AND(J11>=4000,J11<5000),"4000=<5000 AZN",IF(AND(J11>=5000,),"5000=< AZN")))))) -> 2000=<3000 AZN | L11: =H11-J11 -> 6.31 | M11: =IF(L11<0,"menfi","musbet") -> musbet | N11: =_xlfn.CONCAT(A11," ",B11," ",C11) -> Reyhanə Abbasbəyli 36531
A12: Aidə | B12: Təhmin | C12: 35871 | D12: =YEAR(C12) -> 1998 | E12: =2025-D12 -> 27 | F12: =IF(AND(E12>=0,E12<20),"0=<20",IF(AND(E12>=20,E12<30),"20=<30",IF(AND(E12>=30,E12<40),"30=<40",IF(AND(E12>=40,E12<60),"40=<60",IF(AND(E12>=60),"60=<"))))) -> 20=<30 | G12: Lənkəran | H12: 4269.83 | I12: =IF(AND(H12<1000),"<1000 AZN",IF(AND(H12>=1000,H12<2000),"1000=<2000 AZN",IF(AND(H12>=2000,H12<3000),"2000=<3000 AZN",IF(AND(H12>=3000,H12<4000),"3000=<4000 AZN",IF(AND(H12>=4000,H12<5000),"4000=<5000 AZN",IF(AND(H12>=5000,),"5000=< AZN")))))) -> 4000=<5000 AZN | J12: 4816.49 | K12: =IF(AND(J12<1000),"<1000 AZN",IF(AND(J12>=1000,J12<2000),"1000=<2000 AZN",IF(AND(J12>=2000,J12<3000),"2000=<3000 AZN",IF(AND(J12>=3000,J12<4000),"3000=<4000 AZN",IF(AND(J12>=4000,J12<5000),"4000=<5000 AZN",IF(AND(J12>=5000,),"5000=< AZN")))))) -> 4000=<5000 AZN | L12: =H12-J12 -> -546.66 | M12: =IF(L12<0,"menfi","musbet") -> menfi | N12: =_xlfn.CONCAT(A12," ",B12," ",C12) -> Aidə Təhmin 35871
A13: Hüseyn | B13: Talıbzadə | C13: 32529 | D13: =YEAR(C13) -> 1989 | E13: =2025-D13 -> 36 | F13: =IF(AND(E13>=0,E13<20),"0=<20",IF(AND(E13>=20,E13<30),"20=<30",IF(AND(E13>=30,E13<40),"30=<40",IF(AND(E13>=40,E13<60),"40=<60",IF(AND(E13>=60),"60=<"))))) -> 30=<40 | G13: Quba | H13: 3613.68 | I13: =IF(AND(H13<1000),"<1000 AZN",IF(AND(H13>=1000,H13<2000),"1000=<2000 AZN",IF(AND(H13>=2000,H13<3000),"2000=<3000 AZN",IF(AND(H13>=3000,H13<4000),"3000=<4000 AZN",IF(AND(H13>=4000,H13<5000),"4000=<5000 AZN",IF(AND(H13>=5000,),"5000=< AZN")))))) -> 3000=<4000 AZN | J13: 802.97 | K13: =IF(AND(J13<1000),"<1000 AZN",IF(AND(J13>=1000,J13<2000),"1000=<2000 AZN",IF(AND(J13>=2000,J13<3000),"2000=<3000 AZN",IF(AND(J13>=3000,J13<4000),"3000=<4000 AZN",IF(AND(J13>=4000,J13<5000),"4000=<5000 AZN",IF(AND(J13>=5000,),"5000=< AZN")))))) -> <1000 AZN | L13: =H13-J13 -> 2810.71 | M13: =IF(L13<0,"menfi","musbet") -> musbet | N13: =_xlfn.CONCAT(A13," ",B13," ",C13) -> Hüseyn Talıbzadə 32529
... A614: Jalə | B614: Bayramov | C614: 33148 | D614: =YEAR(C614) -> 1990 | E614: =2025-D614 -> 35 | F614: =IF(AND(E614>=0,E614<20),"0=<20",IF(AND(E614>=20,E614<30),"20=<30",IF(AND(E614>=30,E614<40),"30=<40",IF(AND(E614>=40,E614<60),"40=<60",IF(AND(E614>=60),"60=<"))))) -> 30=<40 | G614: Şəki | H614: 3349.13 | I614: =IF(AND(H614<1000),"<1000 AZN",IF(AND(H614>=1000,H614<2000),"1000=<2000 AZN",IF(AND(H614>=2000,H614<3000),"2000=<3000 AZN",IF(AND(H614>=3000,H614<4000),"3000=<4000 AZN",IF(AND(H614>=4000,H614<5000),"4000=<5000 AZN",IF(AND(H614>=5000,),"5000=< AZN")))))) -> 3000=<4000 AZN | J614: 336.18 | K614: =IF(AND(J614<1000),"<1000 AZN",IF(AND(J614>=1000,J614<2000),"1000=<2000 AZN",IF(AND(J614>=2000,J614<3000),"2000=<3000 AZN",IF(AND(J614>=3000,J614<4000),"3000=<4000 AZN",IF(AND(J614>=4000,J614<5000),"4000=<5000 AZN",IF(AND(J614>=5000,),"5000=< AZN")))))) -> <1000 AZN | L614: =H614-J614 -> 3012.95 | M614: =IF(L614<0,"menfi","musbet") -> musbet | N614: =_xlfn.CONCAT(A614," ",B614," ",C614) -> Jalə Bayramov 33148
